Workbook

Sheet Overview
A1: Mathematical Modelling Group Project: Project Tracker
A2: PINN for parameter estimation and hidden-state recovery in an SEIRD model with time-varying transmission
A3: Presentation date (input) | B3: 46327 | C3: Blue text on yellow = input. Change it and the Timeline updates.
A4: Submission deadline (presentation minus 7 days) | B4: =B3-7 | C4: PDF: files due at least one week before the scheduled presentation.
A5: Days to submission | B5: =B4-TODAY()
A6: Days to presentation | B6: =B3-TODAY()
A8: Members, roles and progress
A9: Member | B9: Role | C9: Bonus evidence owned | D9: Tasks | E9: Done | F9: % complete
A10: M1 | B10: Motivation and model; first drafts of full notebook and LaTeX report; final integration and submission | C10: Cited sources, methodology write-up | D10: =COUNTIF(Tasks!$B$5:$B$72,A10) | E10: 10 | F10: 1
A11: M2 | B11: Analysis: R0, stability, final size, sensitivity | C11: Analytic validation (final-size check) | D11: =COUNTIF(Tasks!$B$5:$B$72,A11) | E11: =COUNTIFS(Tasks!$B$5:$B$72,A11,Tasks!$F$5:$F$72,"Done") | F11: =IF(D11=0,0,E11/D11)
A12: M3 | B12: Numerical methods and E1 (Euler, RK4, reference solver) | C12: Convergence rates, reference solver | D12: =COUNTIF(Tasks!$B$5:$B$72,A12) | E12: =COUNTIFS(Tasks!$B$5:$B$72,A12,Tasks!$F$5:$F$72,"Done") | F12: =IF(D12=0,0,E12/D12)
A13: M4 | B13: PINN design and synthetic validation (E2-E4) | C13: Ground-truth validation, relative L2 error | D13: =COUNTIF(Tasks!$B$5:$B$72,A13) | E13: =COUNTIFS(Tasks!$B$5:$B$72,A13,Tasks!$F$5:$F$72,"Done") | F13: =IF(D13=0,0,E13/D13)
A14: M5 | B14: Real-data results, comparison and limitations (E5) | C14: Held-out forecast, MAE, RMSE, relative error | D14: =COUNTIF(Tasks!$B$5:$B$72,A14) | E14: =COUNTIFS(Tasks!$B$5:$B$72,A14,Tasks!$F$5:$F$72,"Done") | F14: =IF(D14=0,0,E14/D14)
A15: All | B15: Shared tasks: AI-use log, read-through, rehearsals | C15: AI acknowledgement, explainability | D15: =COUNTIF(Tasks!$B$5:$B$72,A15) | E15: =COUNTIFS(Tasks!$B$5:$B$72,A15,Tasks!$F$5:$F$72,"Done") | F15: =IF(D15=0,0,E15/D15)
A16: Total | D16: =SUM(D10:D15) | E16: =SUM(E10:E15) | F16: =IF(D16=0,0,E16/D16)
A18: Other checklists
A19: Checklist | B19: Sheet | D19: Items | E19: Done | F19: % complete
A20: Submission checklist | B20: Submission | D20: =COUNTA(Submission!$E$5:$E$15) | E20: =COUNTIF(Submission!$E$5:$E$15,"Done") | F20: =IF(D20=0,0,E20/D20)
A21: Bonus evidence | B21: Bonus | D21: =COUNTA(Bonus!$E$5:$E$13) | E21: =COUNTIF(Bonus!$E$5:$E$13,"Done") | F21: =IF(D21=0,0,E21/D21)
A23: Shared conventions (every member and every AI agent)
A24: 1. | B24: Model: SEIRD with s, e, i, r, d as fractions of N. sigma and gamma fixed from the literature; beta(t), mu and initial conditions estimated.
A25: 2. | B25: Parameter names everywhere: beta, sigma, gamma, mu. Time in days.
A26: 3. | B26: Files: notebook.ipynb, report/main.tex, refs.bib, data/, figs/. Random seed 42.
A27: 4. | B27: All figures saved as .eps with no transparency (no alpha in plots).
A28: 5. | B28: Metrics: MAE, RMSE, relative error, relative L2 error, computed on the held-out window only.
A29: 6. | B29: Training/calibration data must never include the held-out forecast window.
A30: 7. | B30: Each member logs AI tools used and their role, and sends the log to M1 (acknowledgement section).
A32: Risk
A33: M1 is the bottleneck. If v1 slips past Friday night, cut the ablation and reduce seeds. Keep the held-out forecast and the baselines; the bonus depends on them.

Sheet Tasks
A1: Task checklist (per member)
A2: Change only the Status column (yellow). Dates turn red if overdue and not Done. 'All' = every member. Deliver-by times are in Notes.
A4: ID | B4: Member | C4: Task | D4: Deliverable / output | E4: Due date | F4: Status | G4: Notes
A5: T01 | B5: M1 | C5: Create skeletons: notebook with E1-E5 headers, main.tex with all sections, refs.bib (with Ebola citations), figs/ | D5: Notebook shell + LaTeX project | E5: 46316 | F5: Done
A6: T02 | B6: M1 | C6: Fix SEIRD equations and shared conventions (2014 Sierra Leone Ebola parameters, seed 42, .eps figures, metrics) | D6: Conventions agreed by all members | E6: 46316 | F6: Done
A7: T03 | B7: M1 | C7: Write introduction, motivation, objectives, assumptions, model section; draw TikZ diagram; conduct comparative analysis of 3 published Ebola models (Legrand 2007, Rivers 2014, Althaus 2014) | D7: Report sections 1-4 | E7: 46317 | F7: Done
A8: T04 | B8: M1 | C8: Notebook setup & M1 deep analysis: model parameters, phase-plane trajectory derivation i(s), nullcline analysis, peak infection formula i_max, herd immunity threshold p_c, and 2D R0 parameter space contours | D8: Notebook parts 1-2 | E8: 46317 | F8: Done
A9: T05 | B9: M1 | C9: Integrate M2, M3, M4 inputs as they arrive (draft late parts with AI; owner replaces them later) | D9: Merged v0 of notebook and report | E9: 46317 | F9: Done | G9: Thu night
A10: T06 | B10: M1 | C10: Send v1 of the complete notebook and LaTeX report (coloured Markdown, equations, algorithms before each code cell) | D10: v1 notebook (.ipynb) + report (.tex) | E10: 46318 | F10: Done | G10: By 8 PM
A11: T07 | B11: M1 | C11: Merge all owners' edits; rerun notebook top-to-bottom; freeze | D11: Frozen final notebook and report | E11: 46319 | F11: Done | G11: Freeze at 10 PM
A12: T08 | B12: M1 | C12: Compile PDF; check .eps files, citations, AI acknowledgement; SUBMIT | D12: Submission package | E12: 46320 | F12: Done | G12: Submit in the morning
A13: T09 | B13: M1 | C13: Merge slide deck from all members | D13: Single deck | E13: 46322 | F13: Done
A14: T10 | B14: M1 | C14: Be ready to present: motivation, published models critique, and model formulation (about 2 min) | D14: Presentation slice | E14: 46326 | F14: Done
A15: T11 | B15: M2 | C15: Derive R0 = beta/(gamma+mu) by the next-generation matrix (write out F and V) | D15: LaTeX snippet | E15: 46317 | F15: Not started
A16: T12 | B16: M2 | C16: Equilibria, Jacobian and stability condition R0*s* < 1 | D16: LaTeX snippet | E16: 46317 | F16: Not started
A17: T13 | B17: M2 | C17: Derive final-size relation ln(s0/s_inf) = R0(1 - s_inf - r0 - d0); verify numerically for 3-5 values of R0 and report relative error | D17: LaTeX snippet + notebook cells + .eps plot | E17: 46317 | F17: Not started
A18: T14 | B18: M2 | C18: Analytic sensitivity indices of R0; Latin hypercube + PRCC sensitivity of peak infections and final size | D18: Notebook cells + .eps plot | E18: 46317 | F18: Not started
A19: T15 | B19: M2 | C19: Deliver all analysis material to M1 | D19: Everything above, handed over | E19: 46317 | F19: Not started | G19: By 10 PM
A20: T16 | B20: M2 | C20: Revise analysis section in v1 | D20: Revised section | E20: 46319 | F20: Not started
A21: T17 | B21: M2 | C21: Build 1-2 slides: analysis (R0, stability, final size) | D21: Slides | E21: 46322 | F21: Not started
A22: T18 | B22: M2 | C22: Be ready to present: analysis (about 2 min) | D22: Presentation slice | E22: 46326 | F22: Not started
A23: T19 | B23: M3 | C23: Implement Euler and RK4 yourselves (vectorised) | D23: Solver code | E23: 46317 | F23: Not started
A24: T20 | B24: M3 | C24: Reference solver reference_solution(params, t): solve_ivp, DOP853, rtol 1e-12, atol 1e-14; share with M4 and M5 | D24: Shared function | E24: 46317 | F24: Not started
A25: T21 | B25: M3 | C25: E1: error vs step size over about 6 values of h; log-log slope via np.polyfit; confirm slopes about 1 and 4 | D25: Convergence plot (.eps) + table | E25: 46317 | F25: Not started
A26: T22 | B26: M3 | C26: Conservation check: s+e+i+r+d = 1 preserved to about 1e-12 | D26: Notebook cell | E26: 46317 | F26: Not started
A27: T23 | B27: M3 | C27: Deliver code and short method explanation to M1 | D27: Handed over | E27: 46317 | F27: Not started | G27: By 10 PM
A28: T24 | B28: M3 | C28: Revise numerical-methods section in v1 | D28: Revised section | E28: 46319 | F28: Not started
A29: T25 | B29: M3 | C29: Build 1-2 slides: numerical methods and E1 | D29: Slides | E29: 46322 | F29: Not started
A30: T26 | B30: M3 | C30: Be ready to present: numerical methods and E1 (about 2 min) | D30: Presentation slice | E30: 46326 | F30: Not started
A31: T27 | B31: M4 | C31: Write the PINN maths: scaled equations, loss L = w_data*L_data + w_ode*L_ode + w_ic*L_ic + w_reg*L_smooth, and why each term exists | D31: LaTeX snippet | E31: 46316 | F31: Not started
A32: T28 | B32: M4 | C32: Implement PyTorch state network + softplus beta(t) network, autograd derivatives, random collocation points, tanh, Adam then L-BFGS | D32: Working PINN module | E32: 46317 | F32: Not started | G32: Deliver by 10 PM
A33: T29 | B33: M4 | C33: E2: forward solve; relative L2 error vs M3 reference, per compartment | D33: Results table + plot | E33: 46317 | F33: Not started
A34: T30 | B34: M4 | C34: E3: inverse problem with known beta(t) (step and sinusoidal); noise 1% and 5%; 3-5 seeds; mean +/- SD of errors | D34: Results table + plots | E34: 46318 | F34: Not started | G34: Run long jobs in background
A35: T31 | B35: M4 | C35: E4: recover hidden e(t) and s(t) from cases and deaths only; report RMSE | D35: Recovered-vs-true plot + RMSE | E35: 46319 | F35: Not started
A36: T32 | B36: M4 | C36: Loss-weight ablation table | D36: Ablation table | E36: 46319 | F36: Not started
A37: T33 | B37: M4 | C37: Review PINN sections of v1 and write PINN limitations (loss balancing, identifiability) | D37: Revised section | E37: 46319 | F37: Not started
A38: T34 | B38: M4 | C38: Build 1-2 slides: PINN design and synthetic validation | D38: Slides | E38: 46322 | F38: Not started
A39: T35 | B39: M4 | C39: Be ready to present: PINN design and synthetic validation (about 2 min) | D39: Presentation slice | E39: 46326 | F39: Not started
A40: T36 | B40: M5 | C40: Acquire real-world 2014 Sierra Leone Ebola outbreak dataset from public GitHub (cmrivers/ebola) and WHO Situation Reports archive; document exact URL, provenance and CC BY 4.0 licence (strictly no synthetic data for real evaluation) | D40: Dataset + citation | E40: 46316 | F40: Not started
A41: T37 | B41: M5 | C41: Preprocess real Sierra Leone outbreak data (120 days: May 25 - Sep 21, 2014; extract cumulative cases/deaths, compute 7-day rolling average, enforce 75/25 chronological train/test split per data/README.md) | D41: data/*.csv + split | E41: 46317 | F41: Not started
...

Sheet Timeline
A1: Project timeline
A2: Submission and presentation rows are linked to the Overview sheet. Other dates are fixed.
A4: Start | B4: End | C4: Weekday | D4: Milestone | E4: Owner(s) | F4: Days from today
A5: 46316 | B5: 46316 | C5: =TEXT(A5,"ddd") | D5: Kickoff. Confirm topic and presentation slot with instructor and the Google Sheet. M1 builds skeletons. M5 picks dataset. | E5: All; M1; M5 | F5: =A5-TODAY()
A6: 46317 | B6: 46317 | C6: =TEXT(A6,"ddd") | D6: M2, M3 and M4 deliver inputs (code, derivations, PINN module) to M1 by 10 PM. | E6: M2, M3, M4 | F6: =A6-TODAY()
A7: 46318 | B7: 46318 | C7: =TEXT(A7,"ddd") | D7: M5 delivers real-data results by 2 PM. M1 sends v1 of notebook and report by 8 PM. | E7: M5; M1 | F7: =A7-TODAY()
A8: 46319 | B8: 46319 | C8: =TEXT(A8,"ddd") | D8: Revision day: everyone revises own sections. Freeze at 10 PM after a clean top-to-bottom notebook rerun. | E8: All | F8: =A8-TODAY()
A9: =Overview!B4 | B9: =Overview!B4 | C9: =TEXT(A9,"ddd") | D9: M1 compiles and SUBMITS (.tex, PDF, .bib, .eps figures, .ipynb). Must be at least 7 days before the presentation. | E9: M1 | F9: =A9-TODAY()
A10: 46321 | B10: 46322 | C10: =TEXT(A10,"ddd") | D10: Slides built (1-2 per member) and merged by M1. | E10: All; M1 | F10: =A10-TODAY()
A11: 46323 | B11: 46324 | C11: =TEXT(A11,"ddd") | D11: Timed rehearsals (10 min), then question drills (5 min). | E11: All | F11: =A11-TODAY()
A12: 46325 | B12: 46326 | C12: =TEXT(A12,"ddd") | D12: Final run-through and buffer. | E12: All | F12: =A12-TODAY()
A13: =Overview!B3 | B13: =Overview!B3 | C13: =TEXT(A13,"ddd") | D13: PRESENTATION (10 min + 5 min questions). Every member explains their contribution and answers questions. | E13: All | F13: =A13-TODAY()

Sheet Submission
A1: Submission checklist (PDF requirements)
A2: M1 verifies every item before submitting. Change only the Status column.
A4: # | B4: Item | C4: Source in PDF | D4: Owner | E4: Status
A5: 1 | B5: Editable .tex file | C5: LaTeX report (3 marks) | D5: M1 | E5: Done
A6: 2 | B6: Compiled PDF | C6: LaTeX report (3 marks) | D6: M1 | E6: Done
A7: 3 | B7: References (.bib) with all data, papers and adapted material cited | C7: LaTeX report; Important Instructions 5 | D7: M5 | E7: Done
A8: 4 | B8: All figure files in .eps format (no transparency) | C8: LaTeX report (3 marks) | D8: M5 | E8: Done
A9: 5 | B9: Report includes introduction, motivation, objectives, assumptions, mathematical formulation, diagrams, analysis (equilibria, stability, sensitivity), simulations, graphs, interpretation | C9: LaTeX report (3 marks) | D9: M1 | E9: Done
A10: 6 | B10: Executable .ipynb runs top to bottom without errors | C10: Jupyter Notebook (2 marks) | D10: M1 | E10: Done
A11: 7 | B11: Notebook has coloured Markdown, equations and algorithms before each code section; plots labelled with interpretations | C11: Jupyter Notebook (2 marks) | D11: M1 | E11: Done
A12: 8 | B12: All AI tools acknowledged with their roles (missing or dishonest disclosure risks a 10-mark penalty) | C12: Important Instructions 5-6 | D12: All | E12: Done
A13: 9 | B13: Submitted at least one week before the presentation | C13: Final Instructions 4 | D13: M1 | E13: Done
A14: 10 | B14: Topic, date and time confirmed with instructor and entered in the Google Sheet | C14: Final Instructions 2 | D14: M1 | E14: Done
A15: 11 | B15: Every member can explain every equation, method and line of code | C15: Important Instructions 4 | D15: All | E15: Done

Sheet Bonus
A1: Bonus-mark evidence tracker (up to 5 marks)
A2: The PDF says using PINNs alone does not earn bonus marks; depth, independent effort and credible validation do. A negative result reported honestly is acceptable.
A4: # | B4: PDF bonus requirement | C4: Evidence we will show | D4: Owner(s) | E4: Status
A5: 1 | B5: Cite verifiable data sources | C5: Cited public dataset with source, access date and licence | D5: M5 | E5: Done
A6: 2 | B6: Clearly explain the advanced methodology | C6: Full PINN derivation: loss terms, autograd, optimiser (Adam then L-BFGS), loss weighting | D6: M4, M1 | E6: Done
A7: 3 | B7: Validate against independent observations or benchmark solutions | C7: Synthetic ground-truth recovery (E2-E4); tight-tolerance solve_ivp reference | D7: M4, M3 | E7: Done
A8: 4 | B8: Validate against analytic results | C8: Final-size relation check; R0 and stability analysis | D8: M2 | E8: Done
A9: 5 | B9: For prediction tasks, use data not included in training or calibration | C9: Held-out forecast window (last ~25%) never used for training or calibration | D9: M5 | E9: Done
A10: 6 | B10: Report quantitative measures (MAE, RMSE, relative error, convergence rates) | C10: MAE, RMSE, relative error and relative L2 error tables; Euler/RK4 convergence slopes (about 1 and 4) | D10: M5, M4, M3 | E10: Done
A11: 7 | B11: Provide appropriate comparison graphs | C11: PINN vs constant-beta vs piecewise-beta vs data; recovered-vs-true hidden states; convergence plot | D11: M5, M4, M3 | E11: Done
A12: 8 | B12: Explain mathematics, assumptions, implementation and limitations thoroughly | C12: Report sections on model, analysis, method and an explicit limitations section | D12: M1, M5 | E12: Done
A13: 9 | B13: Honest comparison with classical fitting | C13: If the PINN does not beat least squares, say so and explain why | D13: M5 | E13: Done
